Workbook

Sheet Read me
A1: How this list was built
A2: 500 horror films compiled from Claude's knowledge of the horror canon (critics' and fan lists such as They Shoot Zombies, Don't They?), not a live ranked pull.
A3: Deliberately weighted to global horror: Southeast, East and South Asia are over-represented versus a typical ranked list, which would be roughly 70% US, UK and Italian.
A4: Archetype tags are a first pass by Claude and unreviewed. Treat them as a draft reading to argue with, not a finding.
A5: Remakes are kept in pairs where useful (Nosferatu 1922/1979/2024, The Fly 1958/1986, Invasion of the Body Snatchers 1956/1978).
A6: Counts on the Archetypes and Regions tabs are formulas and update if you edit the tags.

Sheet Films
A1: # | B1: Title | C1: Year | D1: Decade | E1: Country | F1: Region | G1: Primary archetype | H1: Secondary archetype | I1: Tag status
A2: 1 | B2: The Student of Prague | C2: 1913 | D2: 1910s | E2: Germany | F2: Continental Europe | G2: The Double | H2: The Bargain | I2: First pass, unreviewed
A3: 2 | B3: The Cabinet of Dr. Caligari | C3: 1920 | D3: 1920s | E3: Germany | F3: Continental Europe | G3: Nobody Believes Her | H3: The Voice Inside | I3: First pass, unreviewed
A4: 3 | B4: The Golem | C4: 1920 | D4: 1920s | E4: Germany | F4: Continental Europe | G4: The Thing We Made | I4: First pass, unreviewed
A5: 4 | B5: Häxan | C5: 1922 | D5: 1920s | E5: Sweden | F5: Continental Europe | G5: The Witch at the Edge of the Woods | H5: The Voice Inside | I5: First pass, unreviewed
A6: 5 | B6: Nosferatu | C6: 1922 | D6: 1920s | E6: Germany | F6: Continental Europe | G6: The One Who Feeds | H6: The Contagion | I6: First pass, unreviewed
A7: 6 | B7: The Hands of Orlac | C7: 1924 | D7: 1920s | E7: Austria | F7: Continental Europe | G7: The Body Betrays | I7: First pass, unreviewed
A8: 7 | B8: The Phantom of the Opera | C8: 1925 | D8: 1920s | E8: US | F8: North America | G8: The House Remembers | H8: The Thing Outside | I8: First pass, unreviewed
A9: 8 | B9: Dr. Jekyll and Mr. Hyde | C9: 1931 | D9: 1930s | E9: US | F9: North America | G9: The Double | H9: The Beast Within | I9: First pass, unreviewed
A10: 9 | B10: Dracula | C10: 1931 | D10: 1930s | E10: US | F10: North America | G10: The One Who Feeds | H10: You Invited It In | I10: First pass, unreviewed
A11: 10 | B11: Frankenstein | C11: 1931 | D11: 1930s | E11: US | F11: North America | G11: The Thing We Made | I11: First pass, unreviewed
A12: 11 | B12: Freaks | C12: 1932 | D12: 1930s | E12: US | F12: North America | G12: You Invited It In | I12: First pass, unreviewed
A13: 12 | B13: Island of Lost Souls | C13: 1932 | D13: 1930s | E13: US | F13: North America | G13: The Thing We Made | H13: The Body Betrays | I13: First pass, unreviewed
A14: 13 | B14: The Mummy | C14: 1932 | D14: 1930s | E14: US | F14: North America | G14: The Dead Won't Stay Dead | H14: The Inherited Curse | I14: First pass, unreviewed
A15: 14 | B15: The Old Dark House | C15: 1932 | D15: 1930s | E15: US | F15: North America | G15: The Bad Host | H15: The House Remembers | I15: First pass, unreviewed
A16: 15 | B16: Vampyr | C16: 1932 | D16: 1930s | E16: France | F16: Continental Europe | G16: The One Who Feeds | I16: First pass, unreviewed
A17: 16 | B17: White Zombie | C17: 1932 | D17: 1930s | E17: US | F17: North America | G17: The Dead Won't Stay Dead | I17: First pass, unreviewed
A18: 17 | B18: King Kong | C18: 1933 | D18: 1930s | E18: US | F18: North America | G18: The Thing Outside | I18: First pass, unreviewed
A19: 18 | B19: The Invisible Man | C19: 1933 | D19: 1930s | E19: US | F19: North America | G19: The Thing We Made | H19: The Bargain | I19: First pass, unreviewed
A20: 19 | B20: The Black Cat | C20: 1934 | D20: 1930s | E20: US | F20: North America | G20: The Village Needs Blood | I20: First pass, unreviewed
A21: 20 | B21: Bride of Frankenstein | C21: 1935 | D21: 1930s | E21: US | F21: North America | G21: The Thing We Made | I21: First pass, unreviewed
A22: 21 | B22: The Wolf Man | C22: 1941 | D22: 1940s | E22: US | F22: North America | G22: The Beast Within | H22: The Inherited Curse | I22: First pass, unreviewed
A23: 22 | B23: Cat People | C23: 1942 | D23: 1940s | E23: US | F23: North America | G23: The Beast Within | H23: The Inherited Curse | I23: First pass, unreviewed
A24: 23 | B24: I Walked with a Zombie | C24: 1943 | D24: 1940s | E24: US | F24: North America | G24: The Dead Won't Stay Dead | I24: First pass, unreviewed
A25: 24 | B25: The Seventh Victim | C25: 1943 | D25: 1940s | E25: US | F25: North America | G25: The Witch at the Edge of the Woods | H25: The Village Needs Blood | I25: First pass, unreviewed
A26: 25 | B26: The Uninvited | C26: 1944 | D26: 1940s | E26: US | F26: North America | G26: The House Remembers | H26: The Woman Who Comes Back | I26: First pass, unreviewed
A27: 26 | B27: Dead of Night | C27: 1945 | D27: 1940s | E27: UK | F27: UK & Ireland | G27: The Thing You Took Home | H27: The Double | I27: First pass, unreviewed
A28: 27 | B28: The Picture of Dorian Gray | C28: 1945 | D28: 1940s | E28: US | F28: North America | G28: The Bargain | H28: The Double | I28: First pass, unreviewed
A29: 28 | B29: Mahal | C29: 1949 | D29: 1940s | E29: India | F29: South Asia | G29: The Woman Who Comes Back | H29: The House Remembers | I29: First pass, unreviewed
A30: 29 | B30: Ugetsu | C30: 1953 | D30: 1950s | E30: Japan | F30: East Asia | G30: The Woman Who Comes Back | I30: First pass, unreviewed
A31: 30 | B31: Creature from the Black Lagoon | C31: 1954 | D31: 1950s | E31: US | F31: North America | G31: The Thing Outside | I31: First pass, unreviewed
A32: 31 | B32: Godzilla | C32: 1954 | D32: 1950s | E32: Japan | F32: East Asia | G32: The Thing Outside | I32: First pass, unreviewed
A33: 32 | B33: Them! | C33: 1954 | D33: 1950s | E33: US | F33: North America | G33: The Thing Outside | I33: First pass, unreviewed
A34: 33 | B34: Les Diaboliques | C34: 1955 | D34: 1950s | E34: France | F34: Continental Europe | G34: The Dead Won't Stay Dead | H34: Nobody Believes Her | I34: First pass, unreviewed
A35: 34 | B35: Invasion of the Body Snatchers | C35: 1956 | D35: 1950s | E35: US | F35: North America | G35: The Double | H35: Nobody Believes Her | I35: First pass, unreviewed
A36: 35 | B36: Night of the Demon | C36: 1957 | D36: 1950s | E36: UK | F36: UK & Ireland | G36: The Thing You Took Home | H36: The Book You Shouldn't Read | I36: First pass, unreviewed
A37: 36 | B37: The Curse of Frankenstein | C37: 1957 | D37: 1950s | E37: UK | F37: UK & Ireland | G37: The Thing We Made | I37: First pass, unreviewed
A38: 37 | B38: Dracula (Horror of Dracula) | C38: 1958 | D38: 1950s | E38: UK | F38: UK & Ireland | G38: The One Who Feeds | I38: First pass, unreviewed
A39: 38 | B39: Sumpah Orang Minyak | C39: 1958 | D39: 1950s | E39: Malaysia | F39: Southeast Asia | G39: The Bargain | I39: First pass, unreviewed
A40: 39 | B40: The Blob | C40: 1958 | D40: 1950s | E40: US | F40: North America | G40: The Thing Outside | H40: Nobody Believes Her | I40: First pass, unreviewed
...

Sheet Archetypes
A1: Archetype | B1: The beat | C1: Documented roots | D1: Films (primary) | E1: Films (primary or secondary) | F1: Share of 500
A2: The Woman Who Comes Back | B2: A wronged woman returns from death for her due | C2: Pontianak (Malay); Oiwa, Yotsuya Kaidan (Japanese, 1825); La Llorona (Mexican); Okiku, Banchō Sarayashiki (Japanese) | D2: =COUNTIF(Films!$G$2:$G$501,A2) -> 32 | E2: =COUNTIF(Films!$G$2:$G$501,A2)+COUNTIF(Films!$H$2:$H$501,A2) -> 44 | F2: =E2/500 -> 0.088
A3: The House Remembers | B3: A place holds the wrong done in it | C3: Pliny the Younger's haunted house at Athens, Letters 7.27 (Roman); Okiku's well (Japanese) | D3: =COUNTIF(Films!$G$2:$G$501,A3) -> 35 | E3: =COUNTIF(Films!$G$2:$G$501,A3)+COUNTIF(Films!$H$2:$H$501,A3) -> 44 | F3: =E3/500 -> 0.088
A4: The Inherited Curse | B4: A wrong done long ago lands on you | C4: Mahsuri's curse on Langkawi (Malay); the House of Atreus (Greek) | D4: =COUNTIF(Films!$G$2:$G$501,A4) -> 13 | E4: =COUNTIF(Films!$G$2:$G$501,A4)+COUNTIF(Films!$H$2:$H$501,A4) -> 32 | F4: =E4/500 -> 0.064
A5: The Thing You Took Home | B5: A cursed object carries the harm | C5: Pandora's jar (Greek); tsukumogami, objects that gain spirits (Japanese); keris believed to hold spirits (Malay); The Monkey's Paw (English, 1902) | D5: =COUNTIF(Films!$G$2:$G$501,A5) -> 15 | E5: =COUNTIF(Films!$G$2:$G$501,A5)+COUNTIF(Films!$H$2:$H$501,A5) -> 24 | F5: =E5/500 -> 0.048
A6: The Voice Inside | B6: Something else speaks through someone you love | C6: The Gerasene demoniac (Gospels); the dybbuk (Ashkenazi Jewish); jinn possession, rasukan (Islamic and Malay folk belief); kitsunetsuki, fox possession (Japanese) | D6: =COUNTIF(Films!$G$2:$G$501,A6) -> 25 | E6: =COUNTIF(Films!$G$2:$G$501,A6)+COUNTIF(Films!$H$2:$H$501,A6) -> 42 | F6: =E6/500 -> 0.084
A7: The Bargain | B7: Wealth or power bought from something that will collect | C7: Faust (German); pesugihan, wealth pacts with spirits (Javanese); keeping a toyol or polong (Malay); the smith and the devil, ATU 330 (European) | D7: =COUNTIF(Films!$G$2:$G$501,A7) -> 15 | E7: =COUNTIF(Films!$G$2:$G$501,A7)+COUNTIF(Films!$H$2:$H$501,A7) -> 27 | F7: =E7/500 -> 0.054
A8: The Wrong Child | B8: The child is not what it seems | C8: The changeling (European); the toyol (Malay) | D8: =COUNTIF(Films!$G$2:$G$501,A8) -> 22 | E8: =COUNTIF(Films!$G$2:$G$501,A8)+COUNTIF(Films!$H$2:$H$501,A8) -> 37 | F8: =E8/500 -> 0.074
A9: The Devouring Mother | B9: The one who should protect is the danger, or grief makes her one | C9: Medea and Lamia (Greek); La Llorona (Mexican) | D9: =COUNTIF(Films!$G$2:$G$501,A9) -> 15 | E9: =COUNTIF(Films!$G$2:$G$501,A9)+COUNTIF(Films!$H$2:$H$501,A9) -> 31 | F9: =E9/500 -> 0.062
A10: The Double | B10: The self, or someone you love, is replaced or split | C10: Narcissus (Greek); the doppelgänger (German); the fetch (Irish) | D10: =COUNTIF(Films!$G$2:$G$501,A10) -> 22 | E10: =COUNTIF(Films!$G$2:$G$501,A10)+COUNTIF(Films!$H$2:$H$501,A10) -> 45 | F10: =E10/500 -> 0.09
A11: The Beast Within | B11: A person becomes the animal | C11: Lycaon (Greek, Ovid); harimau jadian, the weretiger (Malay); úlfheðnar wolf-warriors (Norse) | D11: =COUNTIF(Films!$G$2:$G$501,A11) -> 11 | E11: =COUNTIF(Films!$G$2:$G$501,A11)+COUNTIF(Films!$H$2:$H$501,A11) -> 15 | F11: =E11/500 -> 0.03
A12: The One Who Feeds | B12: The dead or undead live on the living | C12: Penanggalan (Malay); strigoi (Romanian); jiangshi (Chinese); vetala (Indian) | D12: =COUNTIF(Films!$G$2:$G$501,A12) -> 34 | E12: =COUNTIF(Films!$G$2:$G$501,A12)+COUNTIF(Films!$H$2:$H$501,A12) -> 37 | F12: =E12/500 -> 0.074
A13: The Dead Won't Stay Dead | B13: What was buried returns, wrong | C13: Izanami (Japanese, Kojiki); draugr (Norse); the zombi (Haitian folk belief); pocong (Malay/Indonesian) | D13: =COUNTIF(Films!$G$2:$G$501,A13) -> 31 | E13: =COUNTIF(Films!$G$2:$G$501,A13)+COUNTIF(Films!$H$2:$H$501,A13) -> 43 | F13: =E13/500 -> 0.086
... A28: The Endless Night (probation) | B28: Trapped in repetition until you change | C28: Sisyphus (Greek); samsara (Hindu/Buddhist) | D28: =COUNTIF(Films!$G$2:$G$501,A28) -> 2 | E28: =COUNTIF(Films!$G$2:$G$501,A28)+COUNTIF(Films!$H$2:$H$501,A28) -> 2 | F28: =E28/500 -> 0.004
A30: Total tags | D30: =SUM(D2:D28) -> 500 | E30: =SUM(E2:E28) -> 796

Sheet Regions
A1: Region | B1: Films | C1: Share
A2: North America | B2: =COUNTIF(Films!$F$2:$F$501,A2) -> 223 | C2: =B2/500 -> 0.446
A3: UK & Ireland | B3: =COUNTIF(Films!$F$2:$F$501,A3) -> 58 | C3: =B3/500 -> 0.116
A4: Continental Europe | B4: =COUNTIF(Films!$F$2:$F$501,A4) -> 77 | C4: =B4/500 -> 0.154
A5: East Asia | B5: =COUNTIF(Films!$F$2:$F$501,A5) -> 47 | C5: =B5/500 -> 0.094
A6: Southeast Asia | B6: =COUNTIF(Films!$F$2:$F$501,A6) -> 34 | C6: =B6/500 -> 0.068
A7: South Asia | B7: =COUNTIF(Films!$F$2:$F$501,A7) -> 16 | C7: =B7/500 -> 0.032
A8: Latin America | B8: =COUNTIF(Films!$F$2:$F$501,A8) -> 18 | C8: =B8/500 -> 0.036
A9: Australia & NZ | B9: =COUNTIF(Films!$F$2:$F$501,A9) -> 15 | C9: =B9/500 -> 0.03
A10: Middle East & North Africa | B10: =COUNTIF(Films!$F$2:$F$501,A10) -> 7 | C10: =B10/500 -> 0.014
A11: Sub-Saharan Africa | B11: =COUNTIF(Films!$F$2:$F$501,A11) -> 5 | C11: =B11/500 -> 0.01
A12: Total | B12: =SUM(B2:B11) -> 500
